<?xml version="1.0" ?>
<sdf version="1.8">
  <world name="warehouse">
    <plugin filename="libignition-gazebo-physics-system.so"
      name="ignition::gazebo::systems::Physics">
    </plugin>
    <plugin filename="libignition-gazebo-user-commands-system.so"
      name="ignition::gazebo::systems::UserCommands">
    </plugin>
    <plugin filename="libignition-gazebo-scene-broadcaster-system.so"
      name="ignition::gazebo::systems::SceneBroadcaster">
    </plugin>
     
    <plugin filename="libignition-gazebo-imu-system.so"
      name="ignition::gazebo::systems::Imu">
    </plugin>
    
    <plugin
      filename="libignition-gazebo-sensors-system.so"
      name="ignition::gazebo::systems::Sensors"/>
      
    <include>
      <uri>model://sun</uri>
    </include>
    
    <!-- A ground plane -->
    <include>
      <uri>model://ground_plane</uri>
    </include>
    
    <include>
      <uri>model://asphalt_plane</uri>
    </include>
    
    <gravity>0 0 -9.8066</gravity>
    <magnetic_field>6e-06 2.3e-05 -4.2e-05</magnetic_field>
    
    <physics name="default_physics" default="0" type="ode">
      <ode>
        <solver>
          <type>quick</type>
          <iters>4</iters>
          <sor>1.3</sor>
          <use_dynamic_moi_rescaling>0</use_dynamic_moi_rescaling>
        </solver>
        <constraints>
          <cfm>0</cfm>
          <erp>0.2</erp>
          <contact_max_correcting_vel>10</contact_max_correcting_vel>
          <contact_surface_layer>0.001</contact_surface_layer>
        </constraints>
      </ode>
      <max_step_size>0.001</max_step_size>
      <real_time_factor>1</real_time_factor>
      <real_time_update_rate>1000</real_time_update_rate>
    </physics>
    
    
  	<!-- Дрон -->
       <model name='iris_with_standoffs'>
    
      <!--   <include>
           <uri>model://iris_with_standoffs</uri>
           <pose>0 0 0.2 0 0 1.57</pose>
         </include> 
         
         <plugin
           name="ArduPilotPlugin" 
           filename="libArduPilotPlugin.so">
         
          <fdm_addr>127.0.0.1</fdm_addr>
          <fdm_port_in>9002</fdm_port_in>
          <fdm_port_out>9003</fdm_port_out>
          <model_name>iris_with_standoffs</model_name>
          <imuName>imu_sensor</imuName>
        
        </plugin>
       </model> -->
         <plugin
           filename="ignition-gazebo-velocity-control-system"
           name="ignition::gazebo::systems::VelocityControl">
         </plugin>
         
         <pose>0 0 0.2 0 0 0</pose>
         <link name='base_link'>
	   <velocity_decay>
	     <linear>0.0</linear>
	     <angular>0.0</angular>
	   </velocity_decay>
      	   <inertial>
             <pose>0 0 0 0 0 0</pose>
             <mass>1.5</mass>
             <inertia>
	       <ixx>0.008</ixx>
               <ixy>0</ixy>
               <ixz>0</ixz>
	       <iyy>0.015</iyy>
	       <iyz>0</iyz>
	       <izz>0.017</izz>
             </inertia>
           </inertial>
           <collision name='base_collision'>
             <pose>0 0 0 0 0 0</pose>
             <geometry>
               <mesh>
                 <uri>model://iris_with_standoffs/meshes/iris_collision.stl</uri>
               </mesh>
             </geometry>
             <surface>
               <contact>
                 <ode>
                   <max_vel>100.0</max_vel>
                   <min_depth>0.001</min_depth>
                 </ode>
               </contact>
               <friction>
                 <ode>
                   <mu>100000.0</mu>
                   <mu2>100000.0</mu2>
                 </ode>
               </friction>
            </surface>
          </collision>
          <collision name='front_left_leg_collision'>
            <pose>0.123 0.22 -0.11 0 0 0</pose>
            <geometry>
              <cylinder>
                <radius>0.005</radius>
                <length>0.17</length>
              </cylinder>
            </geometry>
            <surface>
              <contact>
                <ode>
                  <max_vel>100.0</max_vel>
                  <min_depth>0.001</min_depth>
                </ode>
              </contact>
              <friction>
                <ode>
                  <mu>100000.0</mu>
                  <mu2>100000.0</mu2>
                </ode>
              </friction>
            </surface>
          </collision>
          <collision name='front_right_leg_collision'>
            <pose>0.123 -0.22 -0.11 0 0 0</pose>
            <geometry>
              <cylinder>
                <radius>0.005</radius>
                <length>0.17</length>
              </cylinder>
            </geometry>
            <surface>
              <contact>
                <ode>
                  <max_vel>100.0</max_vel>
                  <min_depth>0.001</min_depth>
                </ode>
              </contact>
              <friction>
                <ode>
                  <mu>100000.0</mu>
                  <mu2>100000.0</mu2>
                </ode>
              </friction>
            </surface>
          </collision>
          <collision name='rear_left_leg_collision'>
            <pose>-0.140 0.21 -0.11 0 0 0</pose>
            <geometry>
              <cylinder>
                <radius>0.005</radius>
                <length>0.17</length>
              </cylinder>
            </geometry>
            <surface>
              <contact>
                <ode>
                  <max_vel>100.0</max_vel>
                  <min_depth>0.001</min_depth>
                </ode>
              </contact>
              <friction>
                <ode>
                  <mu>100000.0</mu>
                  <mu2>100000.0</mu2>
                </ode>
              </friction>
            </surface>
          </collision>
          <collision name='rear_right_leg_collision'>
            <pose>-0.140 -0.21 -0.11 0 0 0</pose>
            <geometry>
              <cylinder>
                <radius>0.005</radius>
                <length>0.17</length>
              </cylinder>
            </geometry>
            <surface>
              <contact>
                <ode>
                  <max_vel>100.0</max_vel>
                  <min_depth>0.001</min_depth>
                </ode>
              </contact>
              <friction>
                <ode>
                  <mu>100000.0</mu>
                  <mu2>100000.0</mu2>
                </ode>
              </friction>
            </surface>
          </collision>

          <visual name='base_visual'>
            <geometry>
              <mesh>
                <uri>model://iris_with_standoffs/meshes/iris.dae</uri>
              </mesh>
            </geometry>
            <material>
              <ambient>0.05 0.05 0.05</ambient>
              <diffuse>0.05 0.05 0.05</diffuse>
              <specular>1 1 1 1</specular>
              <pbr>
                <metal>
                  <metalness>0.5</metalness>
                  <roughness>0.5</roughness>
                </metal>
              </pbr>
            </material>
          </visual>
          <visual name='front_left_leg_visual'>
            <pose>0.123 0.22 -0.11 0 0 0</pose>
            <geometry>
              <cylinder>
                <radius>0.005</radius>
                <length>0.17</length>
              </cylinder>
            </geometry>
            <material>
              <ambient>0.05 0.05 0.05</ambient>
              <diffuse>0.05 0.05 0.05</diffuse>
              <specular>0.01 0.01 0.01 1.0</specular>
              <pbr>
                <metal>
                  <metalness>0.5</metalness>
                  <roughness>0.5</roughness>
                </metal>
              </pbr>
            </material>
          </visual>
          <visual name='front_right_leg_visual'>
            <pose>0.123 -0.22 -0.11 0 0 0</pose>
            <geometry>
              <cylinder>
                <radius>0.005</radius>
                <length>0.17</length>
              </cylinder>
            </geometry>
            <material>
              <ambient>0.05 0.05 0.05</ambient>
              <diffuse>0.05 0.05 0.05</diffuse>
              <specular>0.01 0.01 0.01 1.0</specular>
              <pbr>
                <metal>
                  <metalness>0.5</metalness>
                  <roughness>0.5</roughness>
                </metal>
              </pbr>
            </material>
          </visual>
          <visual name='rear_left_leg_visual'>
            <pose>-0.140 0.21 -0.11 0 0 0</pose>
            <geometry>
              <cylinder>
                <radius>0.005</radius>
                <length>0.17</length>
              </cylinder>
            </geometry>
            <material>
              <ambient>0.05 0.05 0.05</ambient>
              <diffuse>0.05 0.05 0.05</diffuse>
              <specular>0.01 0.01 0.01 1.0</specular>
              <pbr>
                <metal>
                  <metalness>0.5</metalness>
                  <roughness>0.5</roughness>
                </metal>
              </pbr>
            </material>
          </visual>
          <visual name='rear_right_leg_visual'>
            <pose>-0.140 -0.21 -0.11 0 0 0</pose>
            <geometry>
              <cylinder>
                <radius>0.005</radius>
                <length>0.17</length>
              </cylinder>
            </geometry>
            <material>
              <ambient>0.05 0.05 0.05</ambient>
              <diffuse>0.05 0.05 0.05</diffuse>
              <specular>0.01 0.01 0.01 1.0</specular>
              <pbr>
                <metal>
                  <metalness>0.5</metalness>
                  <roughness>0.5</roughness>
                </metal>
              </pbr>
            </material>
          </visual>
        </link>
    
        <link name="livox_link">
          <pose>0 0 0.10 0 0 0</pose>
          <visual name="visual">
            <pose>0 0 0.7 3.14 0 1.57</pose>
            <geometry>
              <mesh>
                <uri>file:///home/alice/gazebo_models_worlds_collection/models/mid-360-asm.stl</uri>
                <scale>0.001 0.001 0.001</scale>
              </mesh>
            </geometry>
          </visual>
            
          <sensor name="livox" type="gpu_lidar">
            <pose>0 0 0 0 0 0</pose>
            <always_on>true</always_on>
            <visualize>true</visualize>
            <update_rate>10</update_rate>
            <topic>/livox/lidar/points</topic>
            <gz_frame_id>livox_link</gz_frame_id>
            <ray>
          
             <scan>
               <horizontal>
                 <samples>2048</samples>
                 <min_angle>-3.14159</min_angle>
                 <max_angle>3.14159</max_angle>
               </horizontal>
               <vertical>
                 <samples>16</samples>
                 <min_angle>-0.35</min_angle>
                 <max_angle>0.35</max_angle>
               </vertical>
             </scan>
            
             <range>
               <min>0.3</min>
               <max>10.0</max>
             </range>
            
             <noise>
               <type>gaussian</type>
               <mean>0.0</mean>
               <stddev>0.01</stddev>
             </noise>   
           </ray>
           <output_type>PointCloud</output_type>
          </sensor>
        </link>
    
        <joint name='livox_joint' type='fixed'>
          <child>livox_link</child>
          <parent>base_link</parent>
        </joint>
    
        <link name='imu_link'>
          <pose>0 0 0 3.14159 0 3.14159</pose>
          <inertial>
            <pose>0 0 0 0 0 0</pose>
            <mass>0.15</mass>
            <inertia>
              <ixx>0.00001</ixx>
              <ixy>0</ixy>
              <ixz>0</ixz>
              <iyy>0.00002</iyy>
              <iyz>0</iyz>
              <izz>0.00002</izz>
            </inertia>
          </inertial>

          <sensor name="imu_sensor" type="imu">
            <pose degrees="true">0 0 0 0 0 0</pose>
            <always_on>1</always_on>
            <update_rate>20</update_rate>
            <topic>imu_sensor</topic>
            <gz_frame_id>imu_link</gz_frame_id>
        
            <imu>
              <angular_velocity>
                <x>
                  <noise type="gaussian">
                    <mean>0.0</mean>
                    <stddev>0.0002</stddev>
                  </noise>
                </x>
                <y>
                  <noise type="gaussian">
                    <mean>0.0</mean>
                    <stddev>0.0002</stddev>
                  </noise>
                </y>
                <z>
                  <noise type="gaussian">
                    <mean>0.0</mean>
                    <stddev>0.0002</stddev>
                  </noise>
                </z>
              </angular_velocity>

              <linear_acceleration>
                <x>
                  <noise type="gaussian">
                    <mean>0.0</mean>
                    <stddev>0.017</stddev>
                  </noise>
                </x>
                <y>
                  <noise type="gaussian">
                    <mean>0.0</mean>
                    <stddev>0.017</stddev>
                  </noise>
                </y>
                <z>
                  <noise type="gaussian">
                    <mean>0.0</mean>
                    <stddev>0.017</stddev>
                  </noise>
                </z>
              </linear_acceleration>
            </imu>
          </sensor>  
        </link>
        
        <joint name='imu_joint' type='fixed'>
          <child>imu_link</child>
          <parent>base_link</parent>
          <axis>
            <xyz>0 0 1</xyz>
            <limit>
              <lower>0</lower>
              <upper>0</upper>
              <effort>0</effort>
              <velocity>0</velocity>
            </limit>
            <dynamics>
              <damping>1.0</damping>
            </dynamics>
          </axis>
        </joint>
        
     <!--   <plugin
           name="ArduPilotPlugin" 
           filename="libArduPilotPlugin.so">
         
          <fdm_addr>127.0.0.1</fdm_addr>
          <fdm_port_in>9003</fdm_port_in> 
          <!--<fdm_port_out>9011</fdm_port_out>
          <model_name>iris_with_standoffs</model_name>
          <imuName>imu_sensor</imuName>
          <enable_lockstep>true</enable_lockstep>
          
          <connectionTimeoutMaxCount>5</connectionTimeoutMaxCount>
                
        </plugin> -->
    
        <link name='rotor_0'>
          <pose>0.13 -0.22 0.023 0 0 0</pose>
          <inertial>
            <pose>0 0 0 0 0 0</pose>
            <mass>0.025</mass>
            <inertia>
              <ixx>9.75e-06</ixx>
              <ixy>0</ixy>
              <ixz>0</ixz>
              <iyy>0.000166704</iyy>
              <iyz>0</iyz>
              <izz>0.000167604</izz>
            </inertia>
          </inertial>
          <collision name='collision'>
            <pose>0 0 0 0 0 0</pose>
            <geometry>
              <cylinder>
                <length>0.005</length>
                <radius>0.1</radius>
              </cylinder>
            </geometry>
          </collision>
          <visual name='visual'>
            <pose>0 0 0 0 0 0</pose>
            <geometry>
              <mesh>
                <scale>1 1 1</scale>
                <uri>model://iris_with_standoffs/meshes/iris_prop_ccw.dae</uri>
              </mesh>
            </geometry>
            <material>
              <ambient>0 0 1</ambient>
              <diffuse>0 0 1</diffuse>
              <specular>1 1 1 1</specular>
              <pbr>
                <metal>
                  <metalness>0.5</metalness>
                  <roughness>0.5</roughness>
                </metal>
              </pbr>
            </material>
          </visual>
        </link>
        <joint name='rotor_0_joint' type='revolute'>
          <child>rotor_0</child>
          <parent>base_link</parent>
          <axis>
            <xyz>0 0 1</xyz>
            <limit>
              <lower>-1e+16</lower>
              <upper>1e+16</upper>
            </limit>
            <dynamics>
              <damping>0.004</damping>
            </dynamics>
          </axis>
        </joint>
        
    <!--    <plugin
          filename="libignition-gazebo-multicopter-motor-model-system.so"
          name="ignition::gazebo::systems::MulticopterMotorModel">
          <motorNumber>0</motorNumber>
          <jointName>rotor_0_joint</jointName>
          <linkName>rotor_0</linkName>
          <turningDirection>ccw</turningDirection>
          <robotNamespace>iris_with_standoffs</robotNamespace>
          <timeConstantUp>0.0125</timeConstantUp>
          <timeConstantDown>0.025</timeConstantDown>
          <maxRotVelocity>1100</maxRotVelocity>
          <motorConstant>8.54858e-06</motorConstant>
          <momentConstant>0.016</momentConstant>
          <commandSubTopic>motor_speed/0</commandSubTopic>
          <rotorDragCoefficient>8.06428e-05</rotorDragCoefficient>
          <rollingMomentCoefficient>1e-06</rollingMomentCoefficient>
          <motorSpeedPubTopic>motor_speed/0</motorSpeedPubTopic>
          <rotorVelocitySlowdownSim>10</rotorVelocitySlowdownSim>

        </plugin> -->
        
        <link name='rotor_1'>
          <pose>-0.13 0.2 0.023 0 0 0</pose>
          <inertial>
            <pose>0 0 0 0 0 0</pose>
            <mass>0.025</mass>
            <inertia>
              <ixx>9.75e-06</ixx>
              <ixy>0</ixy>
              <ixz>0</ixz>
              <iyy>0.000166704</iyy>
              <iyz>0</iyz>
              <izz>0.000167604</izz>
            </inertia>
          </inertial>
          <collision name='collision'>
            <pose>0 0 0 0 0 0</pose>
            <geometry>
              <cylinder>
                <length>0.005</length>
                <radius>0.1</radius>
              </cylinder>
            </geometry>
          </collision>
          <visual name='visual'>
            <pose>0 0 0 0 0 0</pose>
            <geometry>
              <mesh>
                <scale>1 1 1</scale>
                <uri>model://iris_with_standoffs/meshes/iris_prop_ccw.dae</uri>
              </mesh>
            </geometry>
            <material>
              <ambient>0 0 1 1</ambient>
              <diffuse>0 0 1 1</diffuse>
              <specular>1 1 1 1</specular>
              <pbr>
                <metal>
                  <metalness>0.5</metalness>
                  <roughness>0.5</roughness>
                </metal>
              </pbr>
            </material>
          </visual>
        </link>
        <joint name='rotor_1_joint' type='revolute'>
          <child>rotor_1</child>
          <parent>base_link</parent>
          <axis>
            <xyz>0 0 1</xyz>
            <limit>
              <lower>-1e+16</lower>
              <upper>1e+16</upper>
            </limit>
            <dynamics>
              <damping>0.004</damping>
            </dynamics>
          </axis>
        </joint>
        
     <!--   <plugin
          filename="libignition-gazebo-multicopter-motor-model-system.so"
          name="ignition::gazebo::systems::MulticopterMotorModel">
          <motorNumber>1</motorNumber>
          <jointName>rotor_1_joint</jointName>
          <linkName>rotor_1</linkName>
          <turningDirection>ccw</turningDirection>
          <robotNamespace>iris_with_standoffs</robotNamespace>
          <timeConstantUp>0.0125</timeConstantUp>
          <timeConstantDown>0.025</timeConstantDown>
          <maxRotVelocity>1100</maxRotVelocity>
          <motorConstant>8.54858e-06</motorConstant>
          <momentConstant>0.016</momentConstant>
          <commandSubTopic>motor_speed/1</commandSubTopic>
          <rotorDragCoefficient>8.06428e-05</rotorDragCoefficient>
          <rollingMomentCoefficient>1e-06</rollingMomentCoefficient>
          <motorSpeedPubTopic>motor_speed/1</motorSpeedPubTopic>
          <rotorVelocitySlowdownSim>10</rotorVelocitySlowdownSim>

        </plugin> -->
        
        <link name='rotor_2'>
          <pose>0.13 0.22 0.023 0 0 0</pose>
          <inertial>
            <pose>0 0 0 0 0 0</pose>
            <mass>0.025</mass>
            <inertia>
              <ixx>9.75e-06</ixx>
              <ixy>0</ixy>
              <ixz>0</ixz>
              <iyy>0.000166704</iyy>
              <iyz>0</iyz>
              <izz>0.000167604</izz>
            </inertia>
          </inertial>
          <collision name='collision'>
            <pose>0 0 0 0 0 0</pose>
            <geometry>
              <cylinder>
                <length>0.005</length>
                <radius>0.1</radius>
              </cylinder>
            </geometry>
          </collision>
          <visual name='visual'>
            <pose>0 0 0 0 0 0</pose>
            <geometry>
              <mesh>
                <scale>1 1 1</scale>
                <uri>model://iris_with_standoffs/meshes/iris_prop_cw.dae</uri>
              </mesh>
            </geometry>
            <material>
               <ambient>0 1 0</ambient>
               <diffuse>0 1 0</diffuse>
               <specular>1 1 1 1</specular>
               <pbr>
                 <metal>
                   <metalness>0.5</metalness>
                   <roughness>0.5</roughness>
                 </metal>
               </pbr>
            </material>
          </visual>
        </link>
        <joint name='rotor_2_joint' type='revolute'>
          <child>rotor_2</child>
          <parent>base_link</parent>
          <axis>
            <xyz>0 0 1</xyz>
            <limit>
              <lower>-1e+16</lower>
              <upper>1e+16</upper>
            </limit>
            <dynamics>
              <damping>0.004</damping>
            </dynamics>
          </axis>
        </joint>
        
    <!--    <plugin
          filename="libignition-gazebo-multicopter-motor-model-system.so"
          name="ignition::gazebo::systems::MulticopterMotorModel">
          <motorNumber>2</motorNumber>
          <jointName>rotor_2_joint</jointName>
          <linkName>rotor_2</linkName>
          <turningDirection>cw</turningDirection>
          <robotNamespace>iris_with_standoffs</robotNamespace>
          <timeConstantUp>0.0125</timeConstantUp>
          <timeConstantDown>0.025</timeConstantDown>
          <maxRotVelocity>1100</maxRotVelocity>
          <motorConstant>8.54858e-06</motorConstant>
          <momentConstant>0.016</momentConstant>
          <commandSubTopic>motor_speed/2</commandSubTopic>
          <rotorDragCoefficient>8.06428e-05</rotorDragCoefficient>
          <rollingMomentCoefficient>1e-06</rollingMomentCoefficient>
          <motorSpeedPubTopic>motor_speed/2</motorSpeedPubTopic>
          <rotorVelocitySlowdownSim>10</rotorVelocitySlowdownSim>

        </plugin> -->
        
        <link name='rotor_3'>
          <pose>-0.13 -0.2 0.023 0 0 0</pose>
          <inertial>
            <pose>0 0 0 0 0 0</pose>
            <mass>0.025</mass>
            <inertia>
              <ixx>9.75e-06</ixx>
              <ixy>0</ixy>
              <ixz>0</ixz>
              <iyy>0.000166704</iyy>
              <iyz>0</iyz>
              <izz>0.000167604</izz>
            </inertia>
          </inertial>
          <collision name='collision'>
            <pose>0 0 0 0 0 0</pose>
            <geometry>
              <cylinder>
                <length>0.005</length>
                <radius>0.1</radius>
              </cylinder>
            </geometry>
          </collision>
          <visual name='visual'>
            <pose>0 0 0 0 0 0</pose>
            <geometry>
              <mesh>
                <scale>1 1 1</scale>
                <uri>model://iris_with_standoffs/meshes/iris_prop_cw.dae</uri>
              </mesh>
            </geometry>
            <material>
              <ambient>0 1 0</ambient>
              <diffuse>0 1 0</diffuse>
              <specular>1 1 1 1</specular>
              <pbr>
                <metal>
                  <metalness>0.5</metalness>
                  <roughness>0.5</roughness>
                </metal>
              </pbr>
            </material>
          </visual>
        </link>
        <joint name='rotor_3_joint' type='revolute'>
          <child>rotor_3</child>
          <parent>base_link</parent>
          <axis>
            <xyz>0 0 1</xyz>
            <limit>
              <lower>-1e+16</lower>
              <upper>1e+16</upper>
            </limit>
            <dynamics>
              <damping>0.004</damping>
            </dynamics>
          </axis>
        </joint>
        
   <!--     <plugin
          filename="libignition-gazebo-multicopter-motor-model-system.so"
          name="ignition::gazebo::systems::MulticopterMotorModel">
          <motorNumber>3</motorNumber>
          <jointName>rotor_3_joint</jointName>
          <linkName>rotor_3</linkName>
          <turningDirection>cw</turningDirection>
          <robotNamespace>iris_with_standoffs</robotNamespace>
          <timeConstantUp>0.0125</timeConstantUp>
          <timeConstantDown>0.025</timeConstantDown>
          <maxRotVelocity>1100</maxRotVelocity>
          <motorConstant>8.54858e-06</motorConstant>
          <momentConstant>0.016</momentConstant>
          <commandSubTopic>motor_speed/3</commandSubTopic>
          <rotorDragCoefficient>8.06428e-05</rotorDragCoefficient>
          <rollingMomentCoefficient>1e-06</rollingMomentCoefficient>
          <motorSpeedPubTopic>motor_speed/3</motorSpeedPubTopic>
          <rotorVelocitySlowdownSim>10</rotorVelocitySlowdownSim>

        </plugin> -->
        
       </model> 
    
    <!-- SHELVES -->
    <include>
      <name>shelves 1</name>
      <uri>model://shelves_high2</uri>
      <pose>1 3.4 0 0 0 0</pose>
    </include>

    <include>
      <name>shelves 2</name>
      <uri>model://shelves_high2</uri>
      <pose>-4.13394 3.4 0 0 0 0</pose>
    </include>

    <include>
      <name>shelves 3</name>
      <uri>model://shelves_high2</uri>
      <pose>1 4.7 0 0 0 0</pose>
    </include>

    <include>
      <name>shelves 4</name>
      <uri>model://shelves_high2</uri>
      <pose>-4.13394 4.7 0 0 0 0</pose>
    </include>

    <include>
      <name>shelves 5</name>
      <uri>model://shelves_high2_no_collision</uri>
      <pose>1 -1.5 0 0 0 0</pose>
    </include>

    <include>
      <name>shelves 6</name>
      <uri>model://shelves_high2_no_collision</uri>
      <pose>-4.13394 -1.5 0 0 0 0</pose>
    </include>

    <include>
      <name>shelves 7</name>
      <uri>model://shelves_high2_no_collision</uri>
      <pose>1 -2.8 0 0 0 0</pose>
    </include>

    <include>
      <name>shelves 8</name>
      <uri>model://shelves_high2_no_collision</uri>
      <pose>-4.13394 -2.8 0 0 0 0</pose>
    </include>

    <include>
      <name>shelves 9</name>
      <uri>model://shelves_high2_no_collision</uri>
      <pose>1 -7.8 0 0 0 0</pose>
    </include>

    <include>
      <name>shelves 10</name>
      <uri>model://shelves_high2_no_collision</uri>
      <pose>-4.13394 -7.8 0 0 0 0</pose>
    </include>

    <include>
      <name>shelves 11</name>
      <uri>model://shelves_high2_no_collision</uri>
      <pose>1 -9.1 0 0 0 0</pose>
    </include>

    <include>
      <name>shelves 12</name>
      <uri>model://shelves_high2_no_collision</uri>
      <pose>-4.13394 -9.1 0 0 0 0</pose>
    </include>

    
    <!-- =================================
            Ground level
         ================================= -->

    <!-- PALLET 1 -->
<!--    <include>
      <name>pallet 1 box</name>
      <uri>model://big_box3</uri>
      <pose>1.48626 3.390705 0.760253 0 0.000143 -1.57317</pose>
    </include>
    <include>
      <name>pallet 1 support</name>
      <uri>model://europallet</uri>
      <pose>1.48088 3.400944 0.0635 0 0 -1.56736</pose>
    </include>
    <include>
      <name>pallet 4 box</name>
      <uri>model://big_box3</uri>
      <pose>-2.37439 3.440964 0.776474 0 0 -1.59804</pose>
    </include>
    <include>
      <name>pallet 4 support</name>
      <uri>model://europallet</uri>
      <pose>-2.40127 3.415746 0.0635 0 0 -1.5558</pose>
    </include>

    <!-- PALLET 7 -->
<!--    <include>
      <name>pallet 7 box</name>
      <uri>model://big_box4</uri>
      <pose>2.61297 3.464591 0.774725 0 0 -1.59992</pose>
    </include>
    <include>
      <name>pallet 7 support</name>
      <uri>model://europallet</uri>
      <pose>2.59788 3.454115 0.0635 0 0 -1.56921</pose>
    </include>

    <!-- PALLET 10 -->
<!--    <include>
      <name>pallet 10 box</name>
      <uri>model://big_box3</uri>
      <pose>-3.45548 3.349857 0.774725 0 0 -1.56894</pose>
    </include>
    <include>
      <name>pallet 10 support</name>
      <uri>model://europallet</uri>
      <pose>-3.41303 3.343739 0.0635 0 -0 1.56536</pose>
    </include>
<!-- PALLET 11 -->
 <!--   <include>
      <name>pallet 11 box</name>
      <uri>model://big_box4</uri>
      <pose>-4.67439 3.440964 0.776474 0 0 -1.59804</pose>
    </include>
    <include>
      <name>pallet 11 support</name>
      <uri>model://europallet</uri>
      <pose>-4.70127 3.415746 0.0635 0 0 -1.5558</pose>
    </include>

    <!-- PALLET 12 -->
<!--    <include>
      <name>pallet 12 box</name>
      <uri>model://big_box3</uri>
      <pose>-5.95548 3.349857 0.774725 0 0 -1.56894</pose>
    </include>
    <include>
      <name>pallet 12 support</name>
      <uri>model://europallet</uri>
      <pose>-5.91303 3.343739 0.0635 0 -0 1.56536</pose>
    </include>

    <!-- EMPTY PALLET 18 -->
    <include>
      <name>pallet 18 support</name>
      <uri>model://europallet</uri>
      <pose>0.234986 3.337637 0.0635 0 -0 1.56536</pose>
    </include>
    <include>
      <name>pallet 18b support</name>
      <uri>model://europallet</uri>
      <pose>0.134986 3.337637 0.2102 0 -0 1.2</pose>
    </include>
        1st level
         ================================= -->

    <!-- PALLET 2 -->
 <!--     <include>
      <name>pallet 2 box</name>
      <uri>model://big_box3</uri>
      <pose>-3.25548 3.349857 2.3397 0 0 -1.56894</pose>
    </include>
    <include>
      <name>pallet 2 support</name>
      <uri>model://europallet</uri>
      <pose>-3.21303 3.343739 1.6373 0 -0 1.56536</pose>
    </include>


    <!-- PALLET 5 - SMALL BOXES -->
  <!--  <include>
      <name>pallet 5 multi boxes</name>
      <uri>model://pallet_full</uri>
      <pose>0.334986 3.337637 1.63184 0 0 -1.57575</pose>
      <static>true</static>
    </include>

    <!-- PALLET 17 - SMALL BOXES -->
<!--    <include>
      <name>pallet 17 multi boxes</name>
      <uri>model://pallet_full</uri>
      <pose>0.334986 3.337637 2.31 0 0 -1.57575</pose>
      <static>true</static>
    </include>
<!-- PALLET 8 -->
 <!--   <include>
      <name>pallet 8 box</name>
      <uri>model://big_box4</uri>
      <pose>2.56918 3.321158 2.35696 0 0 -1.56652</pose>
    </include>
    <include>
      <name>pallet 8 support</name>
      <uri>model://europallet</uri>
      <pose>2.64128 3.308661 1.64676 0 0 -1.55378</pose>
    </include>

    <!-- PALLET 9 -->
  <!--  <include>
      <name>pallet 9 box</name>
      <uri>model://big_box4</uri>
      <pose>-2.30257 2.987644 2.35696 0 0 -1.57937</pose>
    </include>
    <include>
      <name>pallet 9 support</name>
      <uri>model://europallet</uri>
      <pose>-2.28744 2.915349 1.64676 0 -0 1.5541</pose>
    </include>

    <!-- PALLET 13 -->
 <!--   <include>
      <name>pallet 13 box</name>
      <uri>model://big_box3</uri>
      <pose>-4.67439 3.440964 2.35696 0 0 -1.59804</pose>
    </include>
    <include>
      <name>pallet 13 support</name>
      <uri>model://europallet</uri>
      <pose>-4.70127 3.415746 1.64676 0 0 -1.5558</pose>
    </include>
<!-- PALLET 14 -->
<!--    <include>
      <name>pallet 14 box</name>
      <uri>model://big_box4</uri>
      <pose>-5.95548 3.349857 2.35696 0 0 -1.56894</pose>
    </include>
    <include>
      <name>pallet 14 support</name>
      <uri>model://europallet</uri>
      <pose>-5.91303 3.343739 1.64676 0 -0 1.56536</pose>
    </include>

    <!-- PALLET 19 -->
  <!--  <include>
      <name>pallet 19 box</name>
      <uri>model://big_box3</uri>
      <pose>-0.8 3.337637 2.3397 0 0 -1.56894</pose>
    </include>
    <include>
      <name>pallet 19 support</name>
      <uri>model://europallet</uri>
      <pose>-0.8 3.337637 1.6373 0 -0 1.56536</pose>
    </include> 


    <!-- =================================
            2nd level
         ================================= -->

    <!-- PALLET 6 - SMALL BOXES -->
    <include>
      <name>pallet 6 multi boxes</name>
      <uri>model://pallet_full</uri>
      <pose>-2.18966 3.351916 3.27046 0 0 -1.58092</pose>
      <static>true</static>
    </include>
<!-- PALLET 15 - SMALL BOXES -->
    <include>
      <name>pallet 15 multi boxes</name>
      <uri>model://pallet_full</uri>
      <pose>-4.68966 3.351916 3.27046 0 0 -1.58092</pose>
      <static>true</static>
    </include>

    <!-- PALLET 16 - SMALL BOXES -->
 <!--   <include>
      <name>pallet 16 multi boxes</name>
      <uri>model://pallet_full</uri>
      <pose>-5.88966 3.351916 3.27046 0 0 -1.58092</pose>
      <static>true</static>
    </include>


    <!-- PALLET 20 -->
 <!--   <include>
      <name>pallet 20 box</name>
      <uri>model://big_box4</uri>
      <pose>-3.25548 3.349857 3.97286 0 0 -1.56894</pose>
    </include>
    <include>
      <name>pallet 20 support</name>
      <uri>model://europallet</uri>
      <pose>-3.21303 3.343739 3.27046 0 -0 1.56536</pose>
    </include>
<!-- PALLET 21 -->
  <!--  <include>
      <name>pallet 21 box</name>
      <uri>model://big_box3</uri>
      <pose>2.56918 3.321158 3.97286 0 0 -1.56652</pose>
    </include>
    <include>
      <name>pallet 21 support</name>
      <uri>model://europallet</uri>
      <pose>2.64128 3.308661 3.27046 0 0 -1.55378</pose>
    </include>

    <!-- PALLET 22 -->
 <!--   <include>
      <name>pallet 22 box</name>
      <uri>model://big_box4</uri>
      <pose>-0.8 3.337637 3.97286 0 0 -1.56894</pose>
    </include>
    <include>
      <name>pallet 22 support</name>
      <uri>model://europallet</uri>
      <pose>-0.8 3.337637 3.27046 0 -0 1.56536</pose>
    </include>


    <!-- =================================
            Shelves B - Ground level
         ================================= -->
<!-- PALLET 1 -->
 <!--   <include>
      <name>pallet B-0-1 box</name>
      <uri>model://big_box3</uri>
      <pose>1.48626 -1.5 0.760253 0 0.000143 1.57317</pose>
    </include>
    <include>
      <name>pallet B-0-1 support</name>
      <uri>model://europallet</uri>
      <pose>1.48088 -1.5 0.0635 0 0 1.56736</pose>
    </include>

    <!-- PALLET 7 -->
  <!--  <include>
      <name>pallet B-0-2 box</name>
      <uri>model://big_box4</uri>
      <pose>2.9 -1.5 0.774725 0 0 1.59992</pose>
    </include>
    <include>
      <name>pallet B-0-2 support</name>
      <uri>model://europallet</uri>
      <pose>2.9 -1.5 0.0635 0 0 1.56921</pose>
    </include>


    <!-- =================================
            Shelves B - 1st level
         ================================= -->
<!-- PALLET 1 -->
 <!--   <include>
      <name>pallet B-1-1 box</name>
      <uri>model://big_box3</uri>
      <pose>1.6 -1.5 2.30 0 0.000143 1.57317</pose>
      <static>true</static>
    </include>
    <include>
      <name>pallet B-1-1-1 support</name>
      <uri>model://europallet</uri>
      <pose>1.6 -1.5 1.60 0 0 1.56736</pose>
      <static>true</static>
    </include>

    <!-- PALLET 7 -->
 <!--   <include>
      <name>pallet B-1-2 box</name>
      <uri>model://big_box3</uri>
      <pose>2.9 -1.5 2.30 0 0 1.59992</pose>
      <static>true</static>
    </include>
    <include>
      <name>pallet B-1-2 support</name>
      <uri>model://europallet</uri>
      <pose>2.9 -1.5 1.60 0 0 1.56921</pose>
      <static>true</static>
    </include>

    <!-- =================================
            Shelves B - 2st level
         ================================= -->
<!-- PALLET 1 -->
 <!--   <include>
      <name>pallet B-2-1 box</name>
      <uri>model://big_box4</uri>
      <pose>1.6 -1.5 3.97 0 0.000143 1.57317</pose>
      <static>true</static>
    </include>
    <include>
      <name>pallet B-2-1 support</name>
      <uri>model://europallet</uri>
      <pose>1.6 -1.5 3.27 0 0 1.56736</pose>
      <static>true</static>
    </include> 

    <!-- PALLET 7 -->
 <!--   <include>
      <name>pallet B-2-2 box</name>
      <uri>model://big_box3</uri>
      <pose>2.9 -1.5 3.97 0 0 1.59992</pose>
      <static>true</static>
    </include>
    <include>
      <name>pallet B-2-2 support</name>
      <uri>model://europallet</uri>
      <pose>2.9 -1.5 3.27 0 0 1.56921</pose>
      <static>true</static>
    </include>

    <!-- ACCESSORIES -->
<!--    <include>
      <name>wall_1</name>
      <uri>model://brick_wall_1</uri>
      <pose>-8.34545 0 0 0 0 0</pose>
    </include>

    <include>
      <name>wall_2</name>
      <uri>model://brick_wall_2</uri>
      <pose>-3.5 9 0 0 0 -1.57</pose>
    </include> -->
    <model name="wall_1">
      <static>true</static>
      <pose>5 0 2 0 0 0</pose>
      
      <link name="link">
        <collision name="collision">
          <geometry>
            <box>
              <size>0.2 15 4</size>
            </box>
          </geometry>
        </collision>

        <visual name="visual">
          <geometry>
            <box>
              <size>0.2 15 4</size>
            </box>
          </geometry>
        </visual>
      </link>
    </model>
    
    <model name="wall_2">
      <static>true</static>
      <pose>-7 0 2 0 0 0</pose>
      
      <link name="link">
        <collision name="collision">
          <geometry>
            <box>
              <size>0.2 15 4</size>
            </box>
          </geometry>
        </collision>

        <visual name="visual">
          <geometry>
            <box>
              <size>0.2 15 4</size>
            </box>
          </geometry>
        </visual>
      </link>
    </model>
    
  </world>
</sdf>
